<mujoco model="opendoge">
  <compiler angle="radian" meshdir="assets" autolimits="true"/>

  <option cone="elliptic" impratio="100" timestep="0.01"/>

  <default>
    <default class="opendoge">
      <geom friction="0.6" margin="0.001" condim="1" solref="0.01 1"/>
      <joint damping="0.5" armature="0.01" frictionloss="0.2"/>
      <position kp="20" forcerange="-6 6"/>
      <default class="abduction">
        <joint axis="1 0 0"/>
      </default>
      <default class="hip">
        <joint axis="0 1 0" range="-0.785 1.134"/>
      </default>
      <default class="knee">
        <joint axis="0 1 0" range="-2.68 -1.04"/>
        <position forcerange="-9 9"/>
      </default>
      <default class="visual">
        <geom type="mesh" contype="0" conaffinity="0" group="2" rgba="0.79 0.82 0.93 1"/>
      </default>
      <default class="collision">
        <geom group="3" contype="1" conaffinity="2" rgba="0.9 0.5 0.3 0.25"
          friction="0 0 0" margin="0.001" condim="1" solref="0.01 1"/>
        <default class="foot">
          <geom type="sphere" size="0.015" priority="1" rgba="1.0 0.2 0.2 0.4"
            solref="0.01 1" solimp="0.015 1 0.023" margin="0.005" condim="6"
            friction="0.4 0.02 0.01"/>
        </default>
      </default>
    </default>
  </default>

  <asset>
    <mesh name="base_link" file="base_link.STL"/>
    <mesh name="FL_hip" file="FL_hip.STL"/>
    <mesh name="FL_thigh" file="FL_thigh.STL"/>
    <mesh name="FL_calf" file="FL_calf.STL"/>
    <mesh name="FL_foot" file="FL_foot.STL"/>
    <mesh name="FR_hip" file="FR_hip.STL"/>
    <mesh name="FR_thigh" file="FR_thigh.STL"/>
    <mesh name="FR_calf" file="FR_calf.STL"/>
    <mesh name="FR_foot" file="FR_foot.STL"/>
    <mesh name="RL_hip" file="RL_hip.STL"/>
    <mesh name="RL_thigh" file="RL_thigh.STL"/>
    <mesh name="RL_calf" file="RL_calf.STL"/>
    <mesh name="RL_foot" file="RL_foot.STL"/>
    <mesh name="RR_hip" file="RR_hip.STL"/>
    <mesh name="RR_thigh" file="RR_thigh.STL"/>
    <mesh name="RR_calf" file="RR_calf.STL"/>
    <mesh name="RR_foot" file="RR_foot.STL"/>
  </asset>

  <worldbody>
    <body name="base" pos="0 0 0.30" childclass="opendoge">
      <inertial pos="0.000134773648275938 1.36367968484041e-06 0.000770353067310358"
        mass="2.2352588780603"
        fullinertia="0.0054247 0.0099197 0.013453 1.29e-06 -9.59e-05 -2e-07"/>
      <freejoint/>
      <site name="imu" pos="0 0 0.03"/>
      <geom type="mesh" mesh="base_link" class="visual"/>
      <geom name="base1" size="0.085 0.045 0.05" type="box" class="collision"/>

      <body name="FL_hip" pos="0.1425 0.039989 0">
        <inertial pos="-0.0019419 -0.00069982 1.3745e-06"
          quat="-0.265811 0.655274 0.265304 0.655419" mass="0.27308"
          diaginertia="0.00010203 8.98057e-05 8.68843e-05"/>
        <joint name="FL_hip_joint" class="abduction" range="-0.785 0.26"/>
        <geom type="mesh" mesh="FL_hip" class="visual"/>
        <geom name="FL_hip_geom" size="0.03 0.0225" type="cylinder" class="collision"/>
        <body name="FL_thigh" pos="0 0.08615 0">
          <inertial pos="-0.0003843 -0.028095 -0.0056139"
            quat="0.928486 -0.246825 -0.101419 -0.258275" mass="0.344"
            diaginertia="0.000317783 0.00026653 0.000146627"/>
          <joint name="FL_thigh_joint" class="hip" range="-0.785 1.134"/>
          <geom type="mesh" mesh="FL_thigh" class="visual"/>
          <geom name="FL_thigh_geom" size="0.01 0.0125 0.035" pos="0.004 0 -0.028" type="box" class="collision"/>
          <body name="FL_calf" pos="0 0 -0.1">
            <inertial pos="0.0049765 -1.1726e-05 -0.047529" mass="0.023132"
              fullinertia="2.88e-05 2.93e-05 1.05e-06 0 9e-08 0"/>
            <joint name="FL_calf_joint" class="knee" range="-2.68 -1.04"/>
            <geom type="mesh" mesh="FL_calf" class="visual"/>
            <geom name="FL_calf_geom" size="0.01 0.025" pos="0.006 0 -0.04" type="cylinder" class="collision"/>
            <geom type="mesh" mesh="FL_foot" class="visual"/>
            <geom name="FL" pos="-1.19561e-05 0 -0.0993915" class="foot"/>
          </body>
        </body>
      </body>

      <body name="FR_hip" pos="0.1425 -0.040075 0">
        <inertial pos="-0.0019419 0.00069983 1.3735e-06"
          quat="0.265811 0.655274 -0.265304 0.655419" mass="0.27308"
          diaginertia="0.00010203 8.98057e-05 8.68843e-05"/>
        <joint name="FR_hip_joint" class="abduction" range="-0.26 0.785"/>
        <geom type="mesh" mesh="FR_hip" class="visual"/>
        <geom name="FR_hip_geom" size="0.03 0.0225" type="cylinder" class="collision"/>
        <body name="FR_thigh" pos="0 -0.0861 0">
          <inertial pos="-0.00039283 0.028155 -0.0056112"
            quat="0.928391 0.247385 -0.101402 0.258085" mass="0.344"
            diaginertia="0.000317975 0.000266712 0.000146673"/>
          <joint name="FR_thigh_joint" class="hip" range="-0.785 1.134"/>
          <geom type="mesh" mesh="FR_thigh" class="visual"/>
          <geom name="FR_thigh_geom" size="0.01 0.0125 0.035" pos="0.004 0 -0.028" type="box" class="collision"/>
          <body name="FR_calf" pos="0 0 -0.1">
            <inertial pos="0.00497648 -1.1726e-05 -0.0475293" mass="0.0231322"
              fullinertia="2.88e-05 2.93e-05 1.05e-06 0 9e-08 0"/>
            <joint name="FR_calf_joint" class="knee" range="-2.68 -1.04"/>
            <geom type="mesh" mesh="FR_calf" class="visual"/>
            <geom name="FR_calf_geom" size="0.01 0.025" pos="0.006 0 -0.04" type="cylinder" class="collision"/>
            <geom type="mesh" mesh="FR_foot" class="visual"/>
            <geom name="FR" pos="-1.19561e-05 0 -0.0993915" class="foot"/>
          </body>
        </body>
      </body>

      <body name="RL_hip" pos="-0.1425 0.040025 0">
        <inertial pos="0.0019419 -0.00069983 1.3735e-06"
          quat="0.265304 0.655419 -0.265811 0.655274" mass="0.27308"
          diaginertia="0.00010203 8.98057e-05 8.68843e-05"/>
        <joint name="RL_hip_joint" class="abduction" range="-0.785 0.26"/>
        <geom type="mesh" mesh="RL_hip" class="visual"/>
        <geom name="RL_hip_geom" size="0.03 0.0225" type="cylinder" class="collision"/>
        <body name="RL_thigh" pos="0 0.08615 0">
          <inertial pos="-0.0003843 -0.028095 -0.0056139"
            quat="0.928486 -0.246825 -0.101419 -0.258275" mass="0.344"
            diaginertia="0.000317783 0.00026653 0.000146627"/>
          <joint name="RL_thigh_joint" class="hip" range="-0.785 1.134"/>
          <geom type="mesh" mesh="RL_thigh" class="visual"/>
          <geom name="RL_thigh_geom" size="0.01 0.0125 0.035" pos="0.004 0 -0.028" type="box" class="collision"/>
          <body name="RL_calf" pos="0 0 -0.1">
            <inertial pos="0.0049765 -1.1726e-05 -0.047529" mass="0.023132"
              fullinertia="2.88e-05 2.93e-05 1.05e-06 0 9e-08 0"/>
            <joint name="RL_calf_joint" class="knee" range="-2.68 -1.04"/>
            <geom type="mesh" mesh="RL_calf" class="visual"/>
            <geom name="RL_calf_geom" size="0.01 0.025" pos="0.006 0 -0.04" type="cylinder" class="collision"/>
            <geom type="mesh" mesh="RL_foot" class="visual"/>
            <geom name="RL" pos="-1.19561e-05 0 -0.0993915" class="foot"/>
          </body>
        </body>
      </body>

      <body name="RR_hip" pos="-0.1425 -0.040025 0">
        <inertial pos="0.0019419 0.00069982 1.3745e-06"
          quat="-0.265304 0.655419 0.265811 0.655274" mass="0.27308"
          diaginertia="0.00010203 8.98057e-05 8.68843e-05"/>
        <joint name="RR_hip_joint" class="abduction" range="-0.26 0.785"/>
        <geom type="mesh" mesh="RR_hip" class="visual"/>
        <geom name="RR_hip_geom" size="0.03 0.0225" type="cylinder" class="collision"/>
        <body name="RR_thigh" pos="0 -0.08615 0">
          <inertial pos="-0.00039283 0.028155 -0.0056112"
            quat="0.928391 0.247385 -0.101402 0.258085" mass="0.344"
            diaginertia="0.000317975 0.000266712 0.000146673"/>
          <joint name="RR_thigh_joint" class="hip" range="-0.785 1.134"/>
          <geom type="mesh" mesh="RR_thigh" class="visual"/>
          <geom name="RR_thigh_geom" size="0.01 0.0125 0.035" pos="0.004 0 -0.028" type="box" class="collision"/>
          <body name="RR_calf" pos="0 0 -0.1">
            <inertial pos="0.0049765 -1.1726e-05 -0.047529" mass="0.023132"
              fullinertia="2.88e-05 2.93e-05 1.05e-06 0 9e-08 0"/>
            <joint name="RR_calf_joint" class="knee" range="-2.68 -1.04"/>
            <geom type="mesh" mesh="RR_calf" class="visual"/>
            <geom name="RR_calf_geom" size="0.01 0.025" pos="0.006 0 -0.04" type="cylinder" class="collision"/>
            <geom type="mesh" mesh="RR_foot" class="visual"/>
            <geom name="RR" pos="-1.19561e-05 0 -0.0993915" class="foot"/>
          </body>
        </body>
      </body>
    </body>
  </worldbody>

  <actuator>
    <position class="abduction" name="FL_hip" joint="FL_hip_joint"/>
    <position class="hip" name="FL_thigh" joint="FL_thigh_joint"/>
    <position class="knee" name="FL_calf" joint="FL_calf_joint"/>
    <position class="abduction" name="FR_hip" joint="FR_hip_joint"/>
    <position class="hip" name="FR_thigh" joint="FR_thigh_joint"/>
    <position class="knee" name="FR_calf" joint="FR_calf_joint"/>
    <position class="abduction" name="RL_hip" joint="RL_hip_joint"/>
    <position class="hip" name="RL_thigh" joint="RL_thigh_joint"/>
    <position class="knee" name="RL_calf" joint="RL_calf_joint"/>
    <position class="abduction" name="RR_hip" joint="RR_hip_joint"/>
    <position class="hip" name="RR_thigh" joint="RR_thigh_joint"/>
    <position class="knee" name="RR_calf" joint="RR_calf_joint"/>
  </actuator>

  <sensor>
    <gyro site="imu" name="gyro"/>
    <velocimeter site="imu" name="local_linvel"/>
    <framezaxis objtype="site" objname="imu" name="upvector"/>
    <framepos objtype="site" objname="imu" name="global_position"/>
    <framelinvel objtype="site" objname="imu" name="global_linvel"/>
    <framepos objtype="geom" objname="FL" name="FL_pos"/>
    <framepos objtype="geom" objname="FR" name="FR_pos"/>
    <framepos objtype="geom" objname="RL" name="RL_pos"/>
    <framepos objtype="geom" objname="RR" name="RR_pos"/>
    <framelinvel objtype="geom" objname="FL" name="FL_vel"/>
    <framelinvel objtype="geom" objname="FR" name="FR_vel"/>
    <framelinvel objtype="geom" objname="RL" name="RL_vel"/>
    <framelinvel objtype="geom" objname="RR" name="RR_vel"/>
  </sensor>
</mujoco>
